!!python/object:huggingface_hub.community.DiscussionWithDetails
author: VinamraYadav
conflicting_files: null
created_at: 2022-10-07 16:18:28+00:00
diff: null
endpoint: https://huggingface.co
events:
- !!python/object:huggingface_hub.community.DiscussionComment
  _event:
    author:
      avatarUrl: /avatars/f62a04bfe938d55f182286ceba9a4548.svg
      fullname: Vinamra Yadav
      isHf: false
      isOrgMember: false
      isOwner: false
      isPro: false
      name: VinamraYadav
      type: user
    createdAt: '2022-10-07T17:18:28.000Z'
    data:
      edited: false
      editors:
      - VinamraYadav
      hidden: false
      isReport: false
      latest:
        author:
          avatarUrl: /avatars/f62a04bfe938d55f182286ceba9a4548.svg
          fullname: Vinamra Yadav
          isHf: false
          isPro: false
          name: VinamraYadav
          type: user
        html: '<p>I am facing a issue during "Select and Load Model". Can anyone guide
          me how to solve this?</p>

          <p>config_path: /content/configs/v1-inference.yaml<br>ckpt_path: /content/drive/MyDrive/AI/models/sd-v1-4.ckpt<br>..checking
          sha256<br>..hash is correct</p>

          <hr>

          <p>FileNotFoundError                         Traceback (most recent call
          last)<br> in <br>    154<br>    155 if load_on_run_all and ckpt_valid:<br>--&gt;
          156     local_config = OmegaConf.load(f"{ckpt_config_path}")<br>    157     model
          = load_model_from_config(local_config, f"{ckpt_path}", half_precision=half_precision)<br>    158     device
          = torch.device("cuda") if torch.cuda.is_available() else torch.device("cpu")</p>

          <p>/usr/local/lib/python3.7/dist-packages/omegaconf/omegaconf.py in load(file_)<br>    185<br>    186         if
          isinstance(file_, (str, pathlib.Path)):<br>--&gt; 187             with io.open(os.path.abspath(file_),
          "r", encoding="utf-8") as f:<br>    188                 obj = yaml.load(f,
          Loader=get_yaml_loader())<br>    189         elif getattr(file_, "read",
          None):</p>

          <p>FileNotFoundError: [Errno 2] No such file or directory: ''/content/configs/v1-inference.yaml''</p>

          '
        raw: "I am facing a issue during \"Select and Load Model\". Can anyone guide\
          \ me how to solve this?\r\n\r\n\r\nconfig_path: /content/configs/v1-inference.yaml\r\
          \nckpt_path: /content/drive/MyDrive/AI/models/sd-v1-4.ckpt\r\n..checking\
          \ sha256\r\n..hash is correct\r\n---------------------------------------------------------------------------\r\
          \nFileNotFoundError                         Traceback (most recent call\
          \ last)\r\n<ipython-input-12-1123622ed33a> in <module>\r\n    154 \r\n \
          \   155 if load_on_run_all and ckpt_valid:\r\n--> 156     local_config =\
          \ OmegaConf.load(f\"{ckpt_config_path}\")\r\n    157     model = load_model_from_config(local_config,\
          \ f\"{ckpt_path}\", half_precision=half_precision)\r\n    158     device\
          \ = torch.device(\"cuda\") if torch.cuda.is_available() else torch.device(\"\
          cpu\")\r\n\r\n/usr/local/lib/python3.7/dist-packages/omegaconf/omegaconf.py\
          \ in load(file_)\r\n    185 \r\n    186         if isinstance(file_, (str,\
          \ pathlib.Path)):\r\n--> 187             with io.open(os.path.abspath(file_),\
          \ \"r\", encoding=\"utf-8\") as f:\r\n    188                 obj = yaml.load(f,\
          \ Loader=get_yaml_loader())\r\n    189         elif getattr(file_, \"read\"\
          , None):\r\n\r\nFileNotFoundError: [Errno 2] No such file or directory:\
          \ '/content/configs/v1-inference.yaml'"
        updatedAt: '2022-10-07T17:18:28.016Z'
      numEdits: 0
      reactions: []
    id: 63405f64733f9eef46933cd6
    type: comment
  author: VinamraYadav
  content: "I am facing a issue during \"Select and Load Model\". Can anyone guide\
    \ me how to solve this?\r\n\r\n\r\nconfig_path: /content/configs/v1-inference.yaml\r\
    \nckpt_path: /content/drive/MyDrive/AI/models/sd-v1-4.ckpt\r\n..checking sha256\r\
    \n..hash is correct\r\n---------------------------------------------------------------------------\r\
    \nFileNotFoundError                         Traceback (most recent call last)\r\
    \n<ipython-input-12-1123622ed33a> in <module>\r\n    154 \r\n    155 if load_on_run_all\
    \ and ckpt_valid:\r\n--> 156     local_config = OmegaConf.load(f\"{ckpt_config_path}\"\
    )\r\n    157     model = load_model_from_config(local_config, f\"{ckpt_path}\"\
    , half_precision=half_precision)\r\n    158     device = torch.device(\"cuda\"\
    ) if torch.cuda.is_available() else torch.device(\"cpu\")\r\n\r\n/usr/local/lib/python3.7/dist-packages/omegaconf/omegaconf.py\
    \ in load(file_)\r\n    185 \r\n    186         if isinstance(file_, (str, pathlib.Path)):\r\
    \n--> 187             with io.open(os.path.abspath(file_), \"r\", encoding=\"\
    utf-8\") as f:\r\n    188                 obj = yaml.load(f, Loader=get_yaml_loader())\r\
    \n    189         elif getattr(file_, \"read\", None):\r\n\r\nFileNotFoundError:\
    \ [Errno 2] No such file or directory: '/content/configs/v1-inference.yaml'"
  created_at: 2022-10-07 16:18:28+00:00
  edited: false
  hidden: false
  id: 63405f64733f9eef46933cd6
  type: comment
- !!python/object:huggingface_hub.community.DiscussionComment
  _event:
    author:
      avatarUrl: /avatars/f3d068b0c58116d37066345e225b7823.svg
      fullname: Ashi Garg
      isHf: false
      isOrgMember: false
      isOwner: false
      isPro: false
      name: ash56
      type: user
    createdAt: '2023-06-05T15:41:05.000Z'
    data:
      edited: false
      editors:
      - ash56
      hidden: false
      identifiedLanguage:
        language: en
        probability: 0.9692200422286987
      isReport: false
      latest:
        author:
          avatarUrl: /avatars/f3d068b0c58116d37066345e225b7823.svg
          fullname: Ashi Garg
          isHf: false
          isPro: false
          name: ash56
          type: user
        html: '<p>I am facing the exact same issue.<br>Were you able to fix it?</p>

          '
        raw: "I am facing the exact same issue. \nWere you able to fix it?"
        updatedAt: '2023-06-05T15:41:05.410Z'
      numEdits: 0
      reactions: []
    id: 647e02115214d172cbbc9c1e
    type: comment
  author: ash56
  content: "I am facing the exact same issue. \nWere you able to fix it?"
  created_at: 2023-06-05 14:41:05+00:00
  edited: false
  hidden: false
  id: 647e02115214d172cbbc9c1e
  type: comment
is_pull_request: false
merge_commit_oid: null
num: 76
repo_id: CompVis/stable-diffusion-v-1-4-original
repo_type: model
status: open
target_branch: null
title: FileNotFoundError
