!!python/object:huggingface_hub.community.DiscussionWithDetails
author: Zia
conflicting_files: null
created_at: 2023-05-02 11:29:47+00:00
diff: null
endpoint: https://huggingface.co
events:
- !!python/object:huggingface_hub.community.DiscussionComment
  _event:
    author:
      avatarUrl: /avatars/6b4299570347a9d335b0b177028c5f0a.svg
      fullname: Hasan
      isHf: false
      isOrgMember: false
      isOwner: false
      isPro: false
      name: Zia
      type: user
    createdAt: '2023-05-02T12:29:47.000Z'
    data:
      edited: true
      editors:
      - Zia
      hidden: false
      isReport: false
      latest:
        author:
          avatarUrl: /avatars/6b4299570347a9d335b0b177028c5f0a.svg
          fullname: Hasan
          isHf: false
          isPro: false
          name: Zia
          type: user
        html: '<p>I got the following error running stage2 as follows: (created a
          separate conda environment and installed all the required libraries). Stage
          1 worked fine</p>

          <p>image = stage_2(<br>    image=image, prompt_embeds=prompt_embeds, negative_prompt_embeds=negative_embeds,
          generator=generator, output_type="pt"<br>).images<br>pt_to_pil(image)[0].save("./if_stage_II.png")<br>''''''</p>

          <hr>

          <p>TypeError                                 Traceback (most recent call
          last)<br>Cell In[11], line 1<br>----&gt; 1 image = stage_2(<br>      2     image=image,
          prompt_embeds=prompt_embeds, negative_prompt_embeds=negative_embeds, generator=generator,
          output_type="pt"<br>      3 ).images<br>      4 pt_to_pil(image)[0].save("./if_stage_II.png")</p>

          <p>File /opt/conda/lib/python3.9/site-packages/torch/utils/_contextlib.py:115,
          in context_decorator..decorate_context(*args, **kwargs)<br>    112 @functools.wraps(func)<br>    113
          def decorate_context(*args, **kwargs):<br>    114     with ctx_factory():<br>--&gt;
          115         return func(*args, **kwargs)</p>

          <p>TypeError: <strong>call</strong>() got an unexpected keyword argument
          ''image''</p>

          '
        raw: "I got the following error running stage2 as follows: (created a separate\
          \ conda environment and installed all the required libraries). Stage 1 worked\
          \ fine\n\nimage = stage_2(\n    image=image, prompt_embeds=prompt_embeds,\
          \ negative_prompt_embeds=negative_embeds, generator=generator, output_type=\"\
          pt\"\n).images\npt_to_pil(image)[0].save(\"./if_stage_II.png\")\n'''\n---------------------------------------------------------------------------\n\
          TypeError                                 Traceback (most recent call last)\n\
          Cell In[11], line 1\n----> 1 image = stage_2(\n      2     image=image,\
          \ prompt_embeds=prompt_embeds, negative_prompt_embeds=negative_embeds, generator=generator,\
          \ output_type=\"pt\"\n      3 ).images\n      4 pt_to_pil(image)[0].save(\"\
          ./if_stage_II.png\")\n\nFile /opt/conda/lib/python3.9/site-packages/torch/utils/_contextlib.py:115,\
          \ in context_decorator.<locals>.decorate_context(*args, **kwargs)\n    112\
          \ @functools.wraps(func)\n    113 def decorate_context(*args, **kwargs):\n\
          \    114     with ctx_factory():\n--> 115         return func(*args, **kwargs)\n\
          \nTypeError: __call__() got an unexpected keyword argument 'image'"
        updatedAt: '2023-05-02T12:30:33.148Z'
      numEdits: 1
      reactions: []
    id: 6451023b67703e98a3c9768c
    type: comment
  author: Zia
  content: "I got the following error running stage2 as follows: (created a separate\
    \ conda environment and installed all the required libraries). Stage 1 worked\
    \ fine\n\nimage = stage_2(\n    image=image, prompt_embeds=prompt_embeds, negative_prompt_embeds=negative_embeds,\
    \ generator=generator, output_type=\"pt\"\n).images\npt_to_pil(image)[0].save(\"\
    ./if_stage_II.png\")\n'''\n---------------------------------------------------------------------------\n\
    TypeError                                 Traceback (most recent call last)\n\
    Cell In[11], line 1\n----> 1 image = stage_2(\n      2     image=image, prompt_embeds=prompt_embeds,\
    \ negative_prompt_embeds=negative_embeds, generator=generator, output_type=\"\
    pt\"\n      3 ).images\n      4 pt_to_pil(image)[0].save(\"./if_stage_II.png\"\
    )\n\nFile /opt/conda/lib/python3.9/site-packages/torch/utils/_contextlib.py:115,\
    \ in context_decorator.<locals>.decorate_context(*args, **kwargs)\n    112 @functools.wraps(func)\n\
    \    113 def decorate_context(*args, **kwargs):\n    114     with ctx_factory():\n\
    --> 115         return func(*args, **kwargs)\n\nTypeError: __call__() got an unexpected\
    \ keyword argument 'image'"
  created_at: 2023-05-02 11:29:47+00:00
  edited: true
  hidden: false
  id: 6451023b67703e98a3c9768c
  type: comment
is_pull_request: false
merge_commit_oid: null
num: 8
repo_id: DeepFloyd/IF-I-M-v1.0
repo_type: model
status: open
target_branch: null
title: 'TypeError: __call__() got an unexpected keyword argument ''image'' in Stage
  2'
