!!python/object:huggingface_hub.community.DiscussionWithDetails
author: odrec
conflicting_files: null
created_at: 2023-12-15 13:57:15+00:00
diff: null
endpoint: https://huggingface.co
events:
- !!python/object:huggingface_hub.community.DiscussionComment
  _event:
    author:
      avatarUrl: /avatars/ea06bc606dff90b2144d740eb1d3e508.svg
      fullname: rgf
      isHf: false
      isOrgMember: false
      isOwner: false
      isPro: false
      name: odrec
      type: user
    createdAt: '2023-12-15T13:57:15.000Z'
    data:
      edited: false
      editors:
      - odrec
      hidden: false
      identifiedLanguage:
        language: en
        probability: 0.588117778301239
      isReport: false
      latest:
        author:
          avatarUrl: /avatars/ea06bc606dff90b2144d740eb1d3e508.svg
          fullname: rgf
          isHf: false
          isPro: false
          name: odrec
          type: user
        html: "<p>I tried this very simple code which is in the model card</p>\n<pre><code>\
          \    from transformers import AutoModelForCausalLM\n    llm = AutoModelForCausalLM.from_pretrained(\"\
          TheBloke/Nous-Capybara-34B-GGUF\", model_file=\"nous-capybara-34b.Q4_K_M.gguf\"\
          , gpu_layers=0)\n</code></pre>\n<p>and I'm getting this error</p>\n<pre><code>\
          \     \".../venv/lib/python3.10/site-packages/transformers/models/auto/configuration_auto.py\"\
          , line 761, in __getitem__\n      raise KeyError(key)\n      KeyError: 'yi'\n\
          </code></pre>\n"
        raw: "I tried this very simple code which is in the model card\r\n\r\n   \
          \     from transformers import AutoModelForCausalLM\r\n        llm = AutoModelForCausalLM.from_pretrained(\"\
          TheBloke/Nous-Capybara-34B-GGUF\", model_file=\"nous-capybara-34b.Q4_K_M.gguf\"\
          , gpu_layers=0)\r\n\r\nand I'm getting this error\r\n\r\n\r\n         \"\
          .../venv/lib/python3.10/site-packages/transformers/models/auto/configuration_auto.py\"\
          , line 761, in __getitem__\r\n          raise KeyError(key)\r\n        \
          \  KeyError: 'yi'\r\n"
        updatedAt: '2023-12-15T13:57:15.731Z'
      numEdits: 0
      reactions: []
    id: 657c5b3b91915edb920f320b
    type: comment
  author: odrec
  content: "I tried this very simple code which is in the model card\r\n\r\n     \
    \   from transformers import AutoModelForCausalLM\r\n        llm = AutoModelForCausalLM.from_pretrained(\"\
    TheBloke/Nous-Capybara-34B-GGUF\", model_file=\"nous-capybara-34b.Q4_K_M.gguf\"\
    , gpu_layers=0)\r\n\r\nand I'm getting this error\r\n\r\n\r\n         \".../venv/lib/python3.10/site-packages/transformers/models/auto/configuration_auto.py\"\
    , line 761, in __getitem__\r\n          raise KeyError(key)\r\n          KeyError:\
    \ 'yi'\r\n"
  created_at: 2023-12-15 13:57:15+00:00
  edited: false
  hidden: false
  id: 657c5b3b91915edb920f320b
  type: comment
is_pull_request: false
merge_commit_oid: null
num: 6
repo_id: TheBloke/Nous-Capybara-34B-GGUF
repo_type: model
status: open
target_branch: null
title: Key error 'yi'
